/*
 * Decompiled with CFR 0.148.
 *
 * Could not load the following classes:
 *  net.minecraft.block.Block
 *  net.minecraft.block.BlockDoublePlant
 *  net.minecraft.block.BlockGrass
 *  net.minecraft.block.BlockTallGrass
 *  net.minecraft.init.Blocks
 *  net.minecraft.world.World
 *  net.minecraft.world.gen.feature.WorldGenerator
 */
package com.sown.util.world.creation.worldgen;

import java.util.Random;
import net.minecraft.block.Block;
import net.minecraft.block.BlockDoublePlant;
import net.minecraft.block.BlockGrass;
import net.minecraft.block.BlockTallGrass;
import net.minecraft.init.Blocks;
import net.minecraft.world.World;
import net.minecraft.world.gen.feature.WorldGenerator;

public class WorldGenMarsh
extends WorldGenerator {
    @Override
    public boolean generate(World world, Random random, int x, int y, int z) {
        int var6 = x;
        int var7 = z;
        while (y < 63) {
            Block block = world.getBlock(x, y - 1, z);
            if (block == Blocks.water && y < 256 - var6 - 1) {
                for (int var8 = 2; var8 <= 5; ++var8) {
                    world.setBlock(x, y, z, Blocks.grass);
                    world.setBlock(x - 1, y, z, Blocks.grass);
                    world.setBlock(x + 1, y, z, Blocks.grass);
                    world.setBlock(x, y, z - 1, Blocks.grass);
                    world.setBlock(x, y, z + 1, Blocks.grass);
                    world.setBlock(x, y - 1, z, Blocks.dirt);
                    world.setBlock(x, y - 2, z, Blocks.dirt);
                    world.setBlock(x, y - 3, z, Blocks.dirt);
                    world.setBlock(x, y - 4, z, Blocks.dirt);
                    world.setBlock(x, y - 5, z, Blocks.dirt);
                    world.setBlock(x, y - 6, z, Blocks.dirt);
                    world.setBlock(x, y - 7, z, Blocks.dirt);
                    world.setBlock(x, y - 8, z, Blocks.dirt);
                    world.setBlock(x, y - 9, z, Blocks.dirt);
                    world.setBlock(x, y - 10, z, Blocks.dirt);
                    world.setBlock(x, y - 11, z, Blocks.dirt);
                    world.setBlock(x, y - 12, z, Blocks.dirt);
                    world.setBlock(x, y - 13, z, Blocks.dirt);
                    world.setBlock(x, y - 14, z, Blocks.dirt);
                    world.setBlock(x, y - 15, z, Blocks.dirt);
                    world.setBlock(x, y - 16, z, Blocks.dirt);
                    world.setBlock(x, y - 17, z, Blocks.dirt);
                    world.setBlock(x - 1, y - 1, z, Blocks.dirt);
                    world.setBlock(x + 1, y - 1, z, Blocks.dirt);
                    world.setBlock(x, y - 1, z - 1, Blocks.dirt);
                    world.setBlock(x, y - 1, z + 1, Blocks.dirt);
                    world.setBlock(x - 1, y - 2, z, Blocks.dirt);
                    world.setBlock(x + 1, y - 2, z, Blocks.dirt);
                    world.setBlock(x, y - 2, z - 1, Blocks.dirt);
                    world.setBlock(x, y - 2, z + 1, Blocks.dirt);
                    world.setBlock(x - 1, y - 3, z, Blocks.dirt);
                    world.setBlock(x + 1, y - 3, z, Blocks.dirt);
                    world.setBlock(x, y - 3, z - 1, Blocks.dirt);
                    world.setBlock(x, y - 3, z + 1, Blocks.dirt);
                    world.setBlock(x - 1, y - 4, z, Blocks.dirt);
                    world.setBlock(x + 1, y - 4, z, Blocks.dirt);
                    world.setBlock(x, y - 4, z - 1, Blocks.dirt);
                    world.setBlock(x, y - 4, z + 1, Blocks.dirt);
                    world.setBlock(x - 1, y - 5, z, Blocks.dirt);
                    world.setBlock(x + 1, y - 5, z, Blocks.dirt);
                    world.setBlock(x, y - 5, z - 1, Blocks.dirt);
                    world.setBlock(x, y - 5, z + 1, Blocks.dirt);
                    world.setBlock(x - 1, y - 6, z, Blocks.dirt);
                    world.setBlock(x + 1, y - 6, z, Blocks.dirt);
                    world.setBlock(x, y - 6, z - 1, Blocks.dirt);
                    world.setBlock(x, y - 6, z + 1, Blocks.dirt);
                    world.setBlock(x - 1, y - 7, z, Blocks.dirt);
                    world.setBlock(x + 1, y - 7, z, Blocks.dirt);
                    world.setBlock(x, y - 7, z - 1, Blocks.dirt);
                    world.setBlock(x, y - 7, z + 1, Blocks.dirt);
                    world.setBlock(x - 1, y - 8, z, Blocks.dirt);
                    world.setBlock(x + 1, y - 8, z, Blocks.dirt);
                    world.setBlock(x, y - 8, z - 1, Blocks.dirt);
                    world.setBlock(x, y - 8, z + 1, Blocks.dirt);
                    world.setBlock(x - 1, y - 9, z, Blocks.dirt);
                    world.setBlock(x + 1, y - 9, z, Blocks.dirt);
                    world.setBlock(x, y - 9, z - 1, Blocks.dirt);
                    world.setBlock(x, y - 9, z + 1, Blocks.dirt);
                    world.setBlock(x - 1, y - 10, z, Blocks.dirt);
                    world.setBlock(x + 1, y - 10, z, Blocks.dirt);
                    world.setBlock(x, y - 10, z - 1, Blocks.dirt);
                    world.setBlock(x, y - 10, z + 1, Blocks.dirt);
                    world.setBlock(x - 1, y - 11, z, Blocks.dirt);
                    world.setBlock(x + 1, y - 11, z, Blocks.dirt);
                    world.setBlock(x, y - 11, z - 1, Blocks.dirt);
                    world.setBlock(x, y - 11, z + 1, Blocks.dirt);
                    world.setBlock(x - 1, y - 12, z, Blocks.dirt);
                    world.setBlock(x + 1, y - 12, z, Blocks.dirt);
                    world.setBlock(x, y - 12, z - 1, Blocks.dirt);
                    world.setBlock(x, y - 12, z + 1, Blocks.dirt);
                    world.setBlock(x - 1, y - 13, z, Blocks.dirt);
                    world.setBlock(x + 1, y - 13, z, Blocks.dirt);
                    world.setBlock(x, y - 13, z - 1, Blocks.dirt);
                    world.setBlock(x, y - 13, z + 1, Blocks.dirt);
                    world.setBlock(x - 1, y - 14, z, Blocks.dirt);
                    world.setBlock(x + 1, y - 14, z, Blocks.dirt);
                    world.setBlock(x, y - 14, z - 1, Blocks.dirt);
                    world.setBlock(x, y - 14, z + 1, Blocks.dirt);
                    world.setBlock(x - 1, y - 15, z, Blocks.dirt);
                    world.setBlock(x + 1, y - 15, z, Blocks.dirt);
                    world.setBlock(x, y - 15, z - 1, Blocks.dirt);
                    world.setBlock(x, y - 15, z + 1, Blocks.dirt);
                    world.setBlock(x - 1, y - 16, z, Blocks.dirt);
                    world.setBlock(x + 1, y - 16, z, Blocks.dirt);
                    world.setBlock(x, y - 16, z - 1, Blocks.dirt);
                    world.setBlock(x, y - 16, z + 1, Blocks.dirt);
                    if (random.nextInt(3) == 0) {
                        Blocks.double_plant.func_149889_c(world, x, y + 1, z, 2, 2);
                        Blocks.double_plant.func_149889_c(world, x - 1, y + 1, z, 2, 2);
                        Blocks.double_plant.func_149889_c(world, x + 1, y + 1, z, 2, 2);
                        Blocks.double_plant.func_149889_c(world, x, y + 1, z - 1, 2, 2);
                        Blocks.double_plant.func_149889_c(world, x, y + 1, z + 1, 2, 2);
                        continue;
                    }
                    world.setBlock(x, y + 1, z, Blocks.tallgrass, 1, 2);
                    world.setBlock(x - 1, y + 1, z, Blocks.tallgrass, 1, 2);
                    world.setBlock(x + 1, y + 1, z, Blocks.tallgrass, 1, 2);
                    world.setBlock(x, y + 1, z - 1, Blocks.tallgrass, 1, 2);
                    world.setBlock(x, y + 1, z + 1, Blocks.tallgrass, 1, 2);
                }
            } else {
                x = var6 + random.nextInt(4) - random.nextInt(4);
                z = var7 + random.nextInt(4) - random.nextInt(4);
            }
            ++y;
        }
        return true;
    }
}

